2020-12-06 14:39:27,010 ERROR: Exception on /api/publications [POST] [in /home/etudiant/projets/projetReact/petits_gazouillis/venv/lib/python3.7/site-packages/flask/app.py:1892]
Traceback (most recent call last):
  File "/home/etudiant/projets/projetReact/petits_gazouillis/venv/lib/python3.7/site-packages/flask/app.py", line 2447, in wsgi_app
    response = self.full_dispatch_request()
  File "/home/etudiant/projets/projetReact/petits_gazouillis/venv/lib/python3.7/site-packages/flask/app.py", line 1952, in full_dispatch_request
    rv = self.handle_user_exception(e)
  File "/home/etudiant/projets/projetReact/petits_gazouillis/venv/lib/python3.7/site-packages/flask_cors/extension.py", line 165, in wrapped_function
    return cors_after_request(app.make_response(f(*args, **kwargs)))
  File "/home/etudiant/projets/projetReact/petits_gazouillis/venv/lib/python3.7/site-packages/flask/app.py", line 1821, in handle_user_exception
    reraise(exc_type, exc_value, tb)
  File "/home/etudiant/projets/projetReact/petits_gazouillis/venv/lib/python3.7/site-packages/flask/_compat.py", line 39, in reraise
    raise value
  File "/home/etudiant/projets/projetReact/petits_gazouillis/venv/lib/python3.7/site-packages/flask/app.py", line 1950, in full_dispatch_request
    rv = self.dispatch_request()
  File "/home/etudiant/projets/projetReact/petits_gazouillis/venv/lib/python3.7/site-packages/flask/app.py", line 1936, in dispatch_request
    return self.view_functions[rule.endpoint](**req.view_args)
  File "/home/etudiant/projets/projetReact/petits_gazouillis/venv/lib/python3.7/site-packages/flask_cors/decorator.py", line 128, in wrapped_function
    resp = make_response(f(*args, **kwargs))
  File "/home/etudiant/projets/projetReact/petits_gazouillis/venv/lib/python3.7/site-packages/flask_httpauth.py", line 163, in decorated
    return f(*args, **kwargs)
  File "/home/etudiant/projets/projetReact/petits_gazouillis/app/api/publications.py", line 55, in creer_publication
    jeton= request.json(["jeton"])
TypeError: 'dict' object is not callable
2020-12-06 14:39:30,528 ERROR: Exception on /api/publications [POST] [in /home/etudiant/projets/projetReact/petits_gazouillis/venv/lib/python3.7/site-packages/flask/app.py:1892]
Traceback (most recent call last):
  File "/home/etudiant/projets/projetReact/petits_gazouillis/venv/lib/python3.7/site-packages/flask/app.py", line 2447, in wsgi_app
    response = self.full_dispatch_request()
  File "/home/etudiant/projets/projetReact/petits_gazouillis/venv/lib/python3.7/site-packages/flask/app.py", line 1952, in full_dispatch_request
    rv = self.handle_user_exception(e)
  File "/home/etudiant/projets/projetReact/petits_gazouillis/venv/lib/python3.7/site-packages/flask_cors/extension.py", line 165, in wrapped_function
    return cors_after_request(app.make_response(f(*args, **kwargs)))
  File "/home/etudiant/projets/projetReact/petits_gazouillis/venv/lib/python3.7/site-packages/flask/app.py", line 1821, in handle_user_exception
    reraise(exc_type, exc_value, tb)
  File "/home/etudiant/projets/projetReact/petits_gazouillis/venv/lib/python3.7/site-packages/flask/_compat.py", line 39, in reraise
    raise value
  File "/home/etudiant/projets/projetReact/petits_gazouillis/venv/lib/python3.7/site-packages/flask/app.py", line 1950, in full_dispatch_request
    rv = self.dispatch_request()
  File "/home/etudiant/projets/projetReact/petits_gazouillis/venv/lib/python3.7/site-packages/flask/app.py", line 1936, in dispatch_request
    return self.view_functions[rule.endpoint](**req.view_args)
  File "/home/etudiant/projets/projetReact/petits_gazouillis/venv/lib/python3.7/site-packages/flask_cors/decorator.py", line 128, in wrapped_function
    resp = make_response(f(*args, **kwargs))
  File "/home/etudiant/projets/projetReact/petits_gazouillis/venv/lib/python3.7/site-packages/flask_httpauth.py", line 163, in decorated
    return f(*args, **kwargs)
  File "/home/etudiant/projets/projetReact/petits_gazouillis/app/api/publications.py", line 55, in creer_publication
    jeton= request.json(["jeton"])
TypeError: 'dict' object is not callable
2020-12-06 14:39:38,672 ERROR: Exception on /api/publications [POST] [in /home/etudiant/projets/projetReact/petits_gazouillis/venv/lib/python3.7/site-packages/flask/app.py:1892]
Traceback (most recent call last):
  File "/home/etudiant/projets/projetReact/petits_gazouillis/venv/lib/python3.7/site-packages/flask/app.py", line 2447, in wsgi_app
    response = self.full_dispatch_request()
  File "/home/etudiant/projets/projetReact/petits_gazouillis/venv/lib/python3.7/site-packages/flask/app.py", line 1952, in full_dispatch_request
    rv = self.handle_user_exception(e)
  File "/home/etudiant/projets/projetReact/petits_gazouillis/venv/lib/python3.7/site-packages/flask_cors/extension.py", line 165, in wrapped_function
    return cors_after_request(app.make_response(f(*args, **kwargs)))
  File "/home/etudiant/projets/projetReact/petits_gazouillis/venv/lib/python3.7/site-packages/flask/app.py", line 1821, in handle_user_exception
    reraise(exc_type, exc_value, tb)
  File "/home/etudiant/projets/projetReact/petits_gazouillis/venv/lib/python3.7/site-packages/flask/_compat.py", line 39, in reraise
    raise value
  File "/home/etudiant/projets/projetReact/petits_gazouillis/venv/lib/python3.7/site-packages/flask/app.py", line 1950, in full_dispatch_request
    rv = self.dispatch_request()
  File "/home/etudiant/projets/projetReact/petits_gazouillis/venv/lib/python3.7/site-packages/flask/app.py", line 1936, in dispatch_request
    return self.view_functions[rule.endpoint](**req.view_args)
  File "/home/etudiant/projets/projetReact/petits_gazouillis/venv/lib/python3.7/site-packages/flask_cors/decorator.py", line 128, in wrapped_function
    resp = make_response(f(*args, **kwargs))
  File "/home/etudiant/projets/projetReact/petits_gazouillis/venv/lib/python3.7/site-packages/flask_httpauth.py", line 163, in decorated
    return f(*args, **kwargs)
  File "/home/etudiant/projets/projetReact/petits_gazouillis/app/api/publications.py", line 55, in creer_publication
    jeton= request.json(["jeton"])
TypeError: 'dict' object is not callable
2020-12-06 14:51:37,293 ERROR: Exception on /api/publications [POST] [in /home/etudiant/projets/projetReact/petits_gazouillis/venv/lib/python3.7/site-packages/flask/app.py:1892]
Traceback (most recent call last):
  File "/home/etudiant/projets/projetReact/petits_gazouillis/venv/lib/python3.7/site-packages/flask/app.py", line 2447, in wsgi_app
    response = self.full_dispatch_request()
  File "/home/etudiant/projets/projetReact/petits_gazouillis/venv/lib/python3.7/site-packages/flask/app.py", line 1952, in full_dispatch_request
    rv = self.handle_user_exception(e)
  File "/home/etudiant/projets/projetReact/petits_gazouillis/venv/lib/python3.7/site-packages/flask_cors/extension.py", line 165, in wrapped_function
    return cors_after_request(app.make_response(f(*args, **kwargs)))
  File "/home/etudiant/projets/projetReact/petits_gazouillis/venv/lib/python3.7/site-packages/flask/app.py", line 1821, in handle_user_exception
    reraise(exc_type, exc_value, tb)
  File "/home/etudiant/projets/projetReact/petits_gazouillis/venv/lib/python3.7/site-packages/flask/_compat.py", line 39, in reraise
    raise value
  File "/home/etudiant/projets/projetReact/petits_gazouillis/venv/lib/python3.7/site-packages/flask/app.py", line 1950, in full_dispatch_request
    rv = self.dispatch_request()
  File "/home/etudiant/projets/projetReact/petits_gazouillis/venv/lib/python3.7/site-packages/flask/app.py", line 1936, in dispatch_request
    return self.view_functions[rule.endpoint](**req.view_args)
  File "/home/etudiant/projets/projetReact/petits_gazouillis/venv/lib/python3.7/site-packages/flask_cors/decorator.py", line 128, in wrapped_function
    resp = make_response(f(*args, **kwargs))
  File "/home/etudiant/projets/projetReact/petits_gazouillis/venv/lib/python3.7/site-packages/flask_httpauth.py", line 163, in decorated
    return f(*args, **kwargs)
  File "/home/etudiant/projets/projetReact/petits_gazouillis/app/api/publications.py", line 55, in creer_publication
    jeton= request.json(["jeton"])
TypeError: 'dict' object is not callable
